Workbook
Name __xlnm.Print_Area: #REF!
Name Add_Budget_Selection: #REF!
Name Analysis_End_Date: #REF!
Name Analysis_End_Month: #REF!
Name Analysis_Length_Months: #REF!
Name Analysis_Length_Years: #REF!
Name Analysis_Start_Date: #REF!
Name Analysis_Start_Month: #REF!
Name Category_1: #REF!
Name Category_2: #REF!
Name Category_3: #REF!
Name Category_4: #REF!
Name Category_5: #REF!
Name Category_6: #REF!
Name Category_7: #REF!
Name Const_End_Date: #REF!
Name Const_End_Month: #REF!
Name Const_Start_Date: #REF!
Name Construction_Int_Rate: #REF!
Name Construction_Length: #REF!
Name Construction_Loan_Amount: #REF!
Name Construction_Module_On?: #REF!
Name Equity_Contribution: #REF!
Name Equity_Share_LP: #REF!
Name Equity_Share_LP_Monthly: #REF!
Name Equity_Share_Sponsor: #REF!
Name Equity_Share_Sponsor_Monthly: #REF!
Name Financing_Module_On: #REF!
Name GL_Module_On?: #REF!
Name Ground_Lease_Years_Remaining: #REF!
Name Growth_Begin_Month: #REF!
Name Investment_Name: #REF!
Name Investment_Period_Months: #REF!
Name IRR_Type: #REF!
Name Jr_Funding_Month: #REF!
Name Label_SF_M2: #REF!
Name Label_Unit_Type: #REF!
Name Label_Unit_Type_Singular: #REF!
Name List_Location: OFFSET(#REF!,0,0,93-COUNTIF(#REF!,""),1)
Name List_Property_Type: OFFSET(#REF!,0,0,1,10-COUNTIF(#REF!,""))
Name Location: #REF!
Name LTC_Actual: #REF!
Name Manager_Salary_Per_Month: #N/A
Name Managersalaryper: #N/A
Name Managersalarypermonth: #N/A
Name MF_1st_Stab_Month: #REF!
Name MF_Module_On: #REF!
Name MF_Units: #REF!
Name MF_Untrended?: #REF!
Name NRA: #REF!
Name Operation_Period_Months: #REF!
Name Operations_Begin_Date: #REF!
Name Operations_Begin_Month: #REF!
Name ORI_1st_Stab_Month: #REF!
Name ORI_Module_On: #REF!
Name ORI_Untrended?: #REF!
Name Per_Unit_Type: #REF!
Name Perm_Debt_Funding: #REF!
Name PermDebt_Funding_Date: #REF!
Name PermDebt_Funding_Month: MAX(#REF!,1)

Sheet Cover Page
N3: =+Dashboard!$E$10
N4: =+Dashboard!$E$12&", "&Dashboard!$E$13
N6: =TODAY()

Sheet Dashboard
C3: Model Dashboard
C5: Assumptions
C7: Transaction Summary | G7: Sources & Uses | L7: Operating Assumptions | Y7: Returns Summary
C9: Transaction Overview | G9: Sources | I9: $ | J9: % | L9: Broader Model General Assumptions | R9: Utility Expenses | U9: Cost / Unit | V9: Year 1 Cost | Y9: Return Summary (Gross)
C10: Investment Name | E10: […] | G10: Total Debt | I10: =+D49 | J10: =+I10/$I$12 | L10: Vacancy | P10: 0.05 | R10: Electric | U10: =+V10/$E$16 | Y10: Scenario 1
C11: Address | E11: […] | G11: Total Equity | I11: =+I12-I10 | J11: =+I11/$I$12 | L11: Rent Increase | P11: 0.03 | R11: Electric - Vacant | U11: =+V11/$E$16 | AA11: Unlevered | AB11: Levered
C12: City | E12: […] | G12: Total Sources | I12: =+I17 | J12: =SUM(J10:J11) | L12: Utility Expense | P12: 0.03 | R12: Water & Sewer | U12: =+V12/$E$16 | Y12: IRR | AA12: =+'Scenario 1'!$E$122 | AB12: =+'Scenario 1'!$E$134
C13: State | E13: […] | L13: Move Outs Per Year | P13: =+O13/E16 | R13: Gas | U13: =+V13/$E$16 | Y13: MOIC | AA13: =+'Scenario 1'!$E$123 | AB13: =+'Scenario 1'!$E$135
C14: Zipcode | E14: […] | G14: Uses | I14: $ | J14: % | L14: Other Income | P14: 0.025 | R14: Cable | U14: =+V14/$E$16 | Y14: Profit ($m) | AA14: =+('Scenario 1'!$J$119+'Scenario 1'!$E$119)/1000000 | AB14: =+('Scenario 1'!$J$131+'Scenario 1'!$E$131)/1000000
C15: Property Type | E15: […] | G15: Purchase Price | I15: =+E32 | J15: =+I15/$I$17 | L15: Inflation Increase | P15: 0.03 | R15: Trash/Garbage | U15: =+V15/$E$16
C16: Units | E16: 72 | G16: Closing and Financing Costs | I16: =+SUM(E34:E40) | J16: =+I16/$I$17 | L16: Insurance Increase | P16: 0.2 | Y16: Return Summary (Gross)
C17: Buildings | E17: […] | G17: Total Uses | I17: =SUM(I15:I16) | J17: =SUM(J15:J16) | Y17: Scenario 2
C18: Year Built | E18: […] | AA18: Unlevered | AB18: Levered
C19: Initial TCCP End Date | E19: […] | G19: Deal Scenario Summary and Stats | L19: Admin Expenses | N19: Growth Rate | O19: Cost / Unit | P19: Yr. 1 Cost | R19: Operating & Maint. | U19: Cost / Unit | V19: Year 1 Cost | Y19: IRR | AA19: =+'Scenario 2'!$E$122 | AB19: =+'Scenario 2'!$E$134
C20: Final Year of LIHTC Restrictions | E20: […] | G20: Unit Occupancy Statistics | I20: # of Units | J20: % | L20: Bad Debt Expense | N20: 0.015 | O20: =+P20/E16 | R20: In-House R&M (per unit) | U20: 0 | V20: =+U20*E16 | Y20: MOIC | AA20: =+'Scenario 2'!$E$123 | AB20: =+'Scenario 2'!$E$135
C21: Total Rentable SF | E21: =+'Rent Roll'!N4 | G21: Occupied Units | I21: ='Rent Roll'!C4 | J21: =+J23-J22 | L21: Replacement Reserves (cost per unit) | N21: 0 | O21: 300 | P21: =+O21*E16 | R21: Turnover (assumed cost per move out) | U21: 700 | V21: =+U21*O13 | Y21: Profit ($m) | AA21: =+('Scenario 2'!$J$119+'Scenario 2'!$E$119)/1000000 | AB21: =+('Scenario 2'!$J$131+'Scenario 2'!$E$131)/1000000
C22: SF / Unit | E22: =+E21/E16 | G22: Vacant Units | I22: ='Rent Roll'!C5 | J22: =I22/I23 | L22: Compliance Fee | N22: 0 | O22: 0 | P22: 0 | R22: Supplies | U22: =+V22/$E$16 | V22: =+(V23*P13)+(V24*E16)*V25
C23: Total Cost / SF | E23: =+I17/E21 | G23: Total Units | I23: =+E16 | J23: =+I23/$I$23 | L23: COVID Late fee (years 1-2) | P23: 0 | R23: Turnover Supplies / Year | V23: 3600 | Y23: Return Summary (Gross)
C24: Total Cost / Unit | E24: =+E22*E23 | R24: Supplies / Unit / Year | V24: 150 | Y24: Scenario 3
C25: TTM Occupancy (insert month / year) | E25: […] | G25: ='Rent Roll'!$J$3 | I25: # of Units | J25: % | L25: Employee Work Schedule Assumptions | R25: Supplies Overage Multiplier | V25: 1.2 | AA25: Unlevered | AB25: Levered
C26: TTM NOI (insert month / year) | E26: […] | G26: ='Rent Roll'!J4 | I26: ='Rent Roll'!K4 | J26: =+I26/$I$31 | L26: Hours per Week | P26: 40 | R26: Appliance/Electrical | U26: 175 | V26: =+(E16/6)*U26 | Y26: IRR | AA26: =+'Scenario 3'!$E$122 | AB26: =+'Scenario 3'!$E$134
G27: ='Rent Roll'!J5 | I27: ='Rent Roll'!K5 | J27: =+I27/$I$31 | L27: Weeks per Year | P27: 52 | R27: HVAC & Plumbing | U27: =+V27/$E$16 | V27: 0 | Y27: MOIC | AA27: =+'Scenario 3'!$E$123 | AB27: =+'Scenario 3'!$E$135
C28: Transaction Assumptions and Statistics | E28: Total Cost | G28: ='Rent Roll'!J6 | I28: ='Rent Roll'!K6 | J28: =+I28/$I$31 | R28: Rent Concessions | U28: 0 | V28: =+U28*$E$16 | Y28: Profit ($m) | AA28: =+('Scenario 3'!$J$119+'Scenario 3'!$E$119)/1000000 | AB28: =+('Scenario 3'!$J$131+'Scenario 3'!$E$131)/1000000
C29: Asking Price | E29: 4300000 | G29: ='Rent Roll'!J7 | I29: ='Rent Roll'!K7 | J29: =+I29/$I$31
C30: Asking Cap Rate (Year 0) | E30: =+'Scenario 0'!E89/Dashboard!E29 | G30: ='Rent Roll'!J8 | I30: ='Rent Roll'!K8 | J30: =+I30/$I$31 | L30: Employee Work Schedule Expenses | M30: Include? | N30: Hourly | O30: Monthly | P30: Yearly | R30: Contract Expenses | V30: Total $
C31: Cost Per Unit (Asking Price) | E31: =+E29/E16 | G31: Total Units | I31: =SUM(I26:I30) | J31: =SUM(J26:J30) | L31: Regional Manager Salary | M31: Yes | N31: =+P31/P26/P27 | O31: 1200 | P31: =++IF(M31="Yes",O31*12,0) | R31: Landscaping/Grounds Contract
C32: Purchase Price | E32: =E29 | L32: Property Manager Salary | M32: Yes | N32: 27 | O32: =+P32/12 | P32: =+IF(M32="Yes",N32*$P$26*$P$27,0) | R32: Fire & Safety System
C33: Cost Per Unit (Purchase Price) | E33: =+E32/$E$16 | G33: ='Rent Roll'!$F$3 | I33: # of Units | J33: % | L33: Assistant Property Manager Salary | M33: No | N33: 20 | O33: =+P33/12 | P33: =+IF(M33="Yes",N33*$P$26*$P$27,0) | R33: Security
C34: Closing Costs | D34: 0.02 | E34: =+$D$34*$E$32 | G34: ='Rent Roll'!F4 | I34: ='Rent Roll'!G4 | J34: =+I34/$I$31 | L34: Commissions / Bonuses | M34: No | N34: 0 | O34: =+P34/12 | P34: =+IF(M34="Yes",N34*$P$26*$P$27,0) | R34: Pest Control
C35: Broker Fees | D35: 0 | E35: =+E32*D35 | G35: ='Rent Roll'!F5 | I35: ='Rent Roll'!G5 | J35: =+I35/$I$31 | L35: Maintenance Salary | M35: Yes | N35: 27 | O35: =+P35/12 | P35: =+IF(M35="Yes",N35*$P$26*$P$27,0) | R35: Misc. Contracts
C36: Rehabilitation Costs | D36: 1000 | E36: =+D36*E16 | G36: ='Rent Roll'!F6 | I36: ='Rent Roll'!G6 | J36: =+I36/$I$31 | L36: Maintenance Assistant Salary | M36: No | N36: 0 | O36: =+P36/12 | P36: =+IF(M36="Yes",N36*$P$26*$P$27,0) | R36: Elevator Costs
C37: Legal Fees | E37: 35000 | G37: ='Rent Roll'!F7 | I37: ='Rent Roll'!G7 | J37: =+I37/$I$31 | L37: Labor Increase % | N37: 0.03 | R37: Snow
C38: Developer Fees | E38: 100000 | G38: ='Rent Roll'!F8 | I38: ='Rent Roll'!G8 | J38: =+I38/$I$31 | R38: Misc. Operating & Maint.
C39: Due Diligence Fees | E39: 25000 | G39: ='Rent Roll'!F9 | I39: ='Rent Roll'!G9 | J39: =+I39/$I$31
C40: Taxes / Title Insurance | E40: 0 | G40: Total Units | I40: =SUM(I34:I39) | J40: =SUM(J34:J39) | L40: Admin Expenses | O40: Cost / Unit | P40: Yr. 1 Cost | R40: Real Estate Taxes and Insurance | V40: Total $
L41: Management Fee (% of Net Rental Income) | P41: 0.05 | R41: Market Value | V41: =+E32*U41
C42: GP / LP Initial Equity Investment | G42: Additional Unit Statistics | L42: Legal Expense | O42: =+P42/$E$16 | P42: 6000 | R42: Less: Taxable Value | V42: =+V41*U42
C43: GP Equity Investment | D43: 0.1 | E43: =+(I17-I10)*D43 | G43: Average Gross Rent | J43: ='Rent Roll'!O4 | L43: Office Expense (Per Unit) | O43: 150 | P43: =+O43*$E$16 | R43: RE Taxes | T43: Prop. Tax Rate (Milage) -> | V43: =+V42*U43/10
C44: LP Equity Investment | D44: =1-D43 | E44: =+(I17-I10)*D44 | G44: Average Effective Rent | J44: ='Rent Roll'!P4 | L44: Travel Cost | O44: =+P44/$E$16 | P44: 6000 | R44: Stormwater Fees
G45: % of Gross Rent | J45: =+J44/J43 | L45: Audit Expense | O45: =+P45/$E$16 | P45: 6500 | R45: Less Discounts | V45: =+V43*U45
...

Sheet Models -->

Sheet Scenario 0
C1: Underwriting Model Scenario 0
D3: Year | E3: 2024 | F3: =+E3+1 | G3: =+F3+1 | H3: =+G3+1 | I3: =+H3+1 | J3: =+I3+1 | K3: =+J3+1 | L3: =+K3+1 | M3: =+L3+1 | ... O3: =+N3+1
C4: Scenario 0 (No Change to Asset)
C6: Income Statement | E6: T12 | F6: 1 | G6: =+F6+1 | H6: =+G6+1 | I6: =+H6+1 | J6: =+I6+1 | K6: =+J6+1 | L6: =+K6+1 | M6: =+L6+1 | N6: =+M6+1 | O6: =+N6+1
A7: GPI | C7: Gross Potential Income | E7: =1561954 | F7: ='Unit Mix'!N26 | G7: ='Unit Mix'!N49 | H7: ='Unit Mix'!N72 | I7: ='Unit Mix'!N95 | J7: =+'Unit Mix'!N118 | K7: =+'Unit Mix'!N141 | L7: =+'Unit Mix'!N164 | M7: =+'Unit Mix'!N187 | N7: =+'Unit Mix'!N210 | O7: ='Unit Mix'!N233
A8: VC | C8: Vacancy Factor | D8: =+Dashboard!$P$10 | E8: 48058 | F8: =+F7*$D$8 | G8: =+G7*$D$8 | H8: =+H7*$D$8 | I8: =+I7*$D$8 | J8: =+J7*$D$8 | K8: =+K7*$D$8 | L8: =+L7*$D$8 | M8: =+M7*$D$8 | ... O8: =+O7*$D$8
C9: Net Rental Income | E9: =+E7-E8 | F9: =+F7-F8 | G9: =+G7-G8 | H9: =+H7-H8 | I9: =+I7-I8 | J9: =+J7-J8 | K9: =+K7-K8 | L9: =+L7-L8 | ... O9: =+O7-O8
A11: OI | C11: Laundry and Other Income | D11: =+Dashboard!$P$14 | E11: 33716 | F11: =+Dashboard!$O$14 | G11: =+F11*(1+$D11) | H11: =+G11*(1+$D11) | I11: =+H11*(1+$D11) | J11: =+I11*(1+$D11) | K11: =+J11*(1+$D11) | L11: =+K11*(1+$D11) | M11: =+L11*(1+$D11) | N11: =+M11*(1+$D11) | O11: =+N11*(1+$D11)
C12: Total Gross Income | E12: =+SUM(E9:E11) | F12: =+SUM(F9:F11) | G12: =+SUM(G9:G11) | H12: =+SUM(H9:H11) | I12: =+SUM(I9:I11) | J12: =+SUM(J9:J11) | K12: =+SUM(K9:K11) | L12: =+SUM(L9:L11) | ... O12: =+SUM(O9:O11)
C13: Gross Income Growth | E13: -- | F13: =+F12/E12-1 | G13: =+G12/F12-1 | H13: =+H12/G12-1 | I13: =+I12/H12-1 | J13: =+J12/I12-1 | K13: =+K12/J12-1 | L13: =+L12/K12-1 | M13: =+M12/L12-1 | ... O13: =+O12/N12-1
C15: Opertating Expenses
A17: BAD | C17: Bad Debt | D17: =+Dashboard!$N$20 | F17: =+Dashboard!P20 | G17: =+F17*(1+$D17) | H17: =+G17*(1+$D17) | I17: =+H17*(1+$D17) | J17: =+I17*(1+$D17) | K17: =+J17*(1+$D17) | L17: =+K17*(1+$D17) | M17: =+L17*(1+$D17) | N17: =+M17*(1+$D17) | O17: =+N17*(1+$D17)
C18: Bad Debt | E18: =+SUM(E17) | F18: =+SUM(F17) | G18: =+SUM(G17) | H18: =+SUM(H17) | I18: =+SUM(I17) | J18: =+SUM(J17) | K18: =+SUM(K17) | L18: =+SUM(L17) | ... O18: =+SUM(O17)
A20: RES | C20: Replacement Reserves | D20: =+Dashboard!$N$21 | E20: =+F20 | F20: =+Dashboard!P21 | G20: =+F20*(1+$D20) | H20: =+G20*(1+$D20) | I20: =+H20*(1+$D20) | J20: =+I20*(1+$D20) | K20: =+J20*(1+$D20) | L20: =+K20*(1+$D20) | M20: =+L20*(1+$D20) | N20: =+M20*(1+$D20) | O20: =+N20*(1+$D20)
A21: COM | C21: Compliance Fee | D21: =+Dashboard!$N$22 | E21: 0 | F21: =+Dashboard!P22 | G21: =+F21*(1+$D21) | H21: =+G21*(1+$D21) | I21: =+H21*(1+$D21) | J21: =+I21*(1+$D21) | K21: =+J21*(1+$D21) | L21: =+K21*(1+$D21) | M21: =+L21*(1+$D21) | N21: =+M21*(1+$D21) | O21: =+N21*(1+$D21)
C22: Total Replacement Reserves | E22: =SUM(E20:E21) | F22: =SUM(F20:F21) | G22: =SUM(G20:G21) | H22: =SUM(H20:H21) | I22: =SUM(I20:I21) | J22: =SUM(J20:J21) | K22: =SUM(K20:K21) | L22: =SUM(L20:L21) | ... O22: =SUM(O20:O21)
A24: REG | C24: Regional Manager Salary | D24: =+Dashboard!$N$37 | F24: =+Dashboard!P31 | G24: =+F24*(1+$D24) | H24: =+G24*(1+$D24) | I24: =+H24*(1+$D24) | J24: =+I24*(1+$D24) | K24: =+J24*(1+$D24) | L24: =+K24*(1+$D24) | M24: =+L24*(1+$D24) | N24: =+M24*(1+$D24) | O24: =+N24*(1+$D24)
A25: MAN | C25: Property Manager Salary | D25: =+Dashboard!$N$37 | F25: =+Dashboard!P32 | G25: =+F25*(1+$D25) | H25: =+G25*(1+$D25) | I25: =+H25*(1+$D25) | J25: =+I25*(1+$D25) | K25: =+J25*(1+$D25) | L25: =+K25*(1+$D25) | M25: =+L25*(1+$D25) | N25: =+M25*(1+$D25) | O25: =+N25*(1+$D25)
A26: ASS | C26: Assistant Manager (over 160 units) | D26: =+Dashboard!$N$37 | F26: =+Dashboard!P33 | G26: =+F26*(1+$D26) | H26: =+G26*(1+$D26) | I26: =+H26*(1+$D26) | J26: =+I26*(1+$D26) | K26: =+J26*(1+$D26) | L26: =+K26*(1+$D26) | M26: =+L26*(1+$D26) | N26: =+M26*(1+$D26) | O26: =+N26*(1+$D26)
A27: PAY | C27: Commissions/Bonuses | D27: =+Dashboard!$N$37 | F27: =+Dashboard!P34 | G27: =+F27*(1+$D27) | H27: =+G27*(1+$D27) | I27: =+H27*(1+$D27) | J27: =+I27*(1+$D27) | K27: =+J27*(1+$D27) | L27: =+K27*(1+$D27) | M27: =+L27*(1+$D27) | N27: =+M27*(1+$D27) | O27: =+N27*(1+$D27)
A28: MAIT | C28: Maintenance Salary | D28: =+Dashboard!$N$37 | F28: =+Dashboard!P35+Dashboard!P36 | G28: =+F28*(1+$D28) | H28: =+G28*(1+$D28) | I28: =+H28*(1+$D28) | J28: =+I28*(1+$D28) | K28: =+J28*(1+$D28) | L28: =+K28*(1+$D28) | M28: =+L28*(1+$D28) | N28: =+M28*(1+$D28) | O28: =+N28*(1+$D28)
C29: Payroll | E29: =SUM(E24:E28) | F29: =SUM(F24:F28) | G29: =SUM(G24:G28) | H29: =SUM(H24:H28) | I29: =SUM(I24:I28) | J29: =SUM(J24:J28) | K29: =SUM(K24:K28) | L29: =SUM(L24:L28) | ... O29: =SUM(O24:O28)
A31: MGMT | C31: Management Fee | D31: =+Dashboard!$P$41 | F31: =+F9*$D$31 | G31: =+G9*$D$31 | H31: =+H9*$D$31 | I31: =+I9*$D$31 | J31: =+J9*$D$31 | K31: =+K9*$D$31 | L31: =+L9*$D$31 | M31: =+M9*$D$31 | ... O31: =+O9*$D$31
A32: LEGAL | C32: Legal Expense | D32: =+Dashboard!$P$15 | F32: =Dashboard!P42 | G32: =+F32*(1+$D32) | H32: =+G32*(1+$D32) | I32: =+H32*(1+$D32) | J32: =+I32*(1+$D32) | K32: =+J32*(1+$D32) | L32: =+K32*(1+$D32) | M32: =+L32*(1+$D32) | N32: =+M32*(1+$D32) | O32: =+N32*(1+$D32)
A33: OFF | C33: Office Expense | D33: =+Dashboard!$P$15 | F33: =Dashboard!P43 | G33: =+F33*(1+$D33) | H33: =+G33*(1+$D33) | I33: =+H33*(1+$D33) | J33: =+I33*(1+$D33) | K33: =+J33*(1+$D33) | L33: =+K33*(1+$D33) | M33: =+L33*(1+$D33) | N33: =+M33*(1+$D33) | O33: =+N33*(1+$D33)
A34: TRAVEL | C34: Travel Cost | D34: =+Dashboard!$P$15 | F34: =Dashboard!P44 | G34: =+F34*(1+$D34) | H34: =+G34*(1+$D34) | I34: =+H34*(1+$D34) | J34: =+I34*(1+$D34) | K34: =+J34*(1+$D34) | L34: =+K34*(1+$D34) | M34: =+L34*(1+$D34) | N34: =+M34*(1+$D34) | O34: =+N34*(1+$D34)
A35: AUD | C35: Audit Expense | D35: =+Dashboard!$P$15 | F35: =Dashboard!P45 | G35: =+F35*(1+$D35) | H35: =+G35*(1+$D35) | I35: =+H35*(1+$D35) | J35: =+I35*(1+$D35) | K35: =+J35*(1+$D35) | L35: =+K35*(1+$D35) | M35: =+L35*(1+$D35) | N35: =+M35*(1+$D35) | O35: =+N35*(1+$D35)
A36: ADV | C36: Advertising | D36: =+Dashboard!$P$15 | F36: =Dashboard!P46 | G36: =+F36*(1+$D36) | H36: =+G36*(1+$D36) | I36: =+H36*(1+$D36) | J36: =+I36*(1+$D36) | K36: =+J36*(1+$D36) | L36: =+K36*(1+$D36) | M36: =+L36*(1+$D36) | N36: =+M36*(1+$D36) | O36: =+N36*(1+$D36)
A37: TRAIN | C37: Training Charge | D37: =+Dashboard!$P$15 | F37: =Dashboard!P47 | G37: =+F37*(1+$D37) | H37: =+G37*(1+$D37) | I37: =+H37*(1+$D37) | J37: =+I37*(1+$D37) | K37: =+J37*(1+$D37) | L37: =+K37*(1+$D37) | M37: =+L37*(1+$D37) | N37: =+M37*(1+$D37) | O37: =+N37*(1+$D37)
A38: BANK | C38: Bank Charges | D38: =+Dashboard!$P$15 | F38: =Dashboard!P48 | G38: =+F38*(1+$D38) | H38: =+G38*(1+$D38) | I38: =+H38*(1+$D38) | J38: =+I38*(1+$D38) | K38: =+J38*(1+$D38) | L38: =+K38*(1+$D38) | M38: =+L38*(1+$D38) | N38: =+M38*(1+$D38) | O38: =+N38*(1+$D38)
A39: BOOK | C39: Bookkeeping | D39: =+Dashboard!$P$15 | F39: =Dashboard!P49 | G39: =+F39*(1+$D39) | H39: =+G39*(1+$D39) | I39: =+H39*(1+$D39) | J39: =+I39*(1+$D39) | K39: =+J39*(1+$D39) | L39: =+K39*(1+$D39) | M39: =+L39*(1+$D39) | N39: =+M39*(1+$D39) | O39: =+N39*(1+$D39)
A40: PAYSERV | C40: Payroll Service | D40: =+Dashboard!$P$15 | F40: =Dashboard!P50 | G40: =+F40*(1+$D40) | H40: =+G40*(1+$D40) | I40: =+H40*(1+$D40) | J40: =+I40*(1+$D40) | K40: =+J40*(1+$D40) | L40: =+K40*(1+$D40) | M40: =+L40*(1+$D40) | N40: =+M40*(1+$D40) | O40: =+N40*(1+$D40)
A41: UNIT | C41: Manager Unit | D41: =+Dashboard!$P$15 | F41: =Dashboard!P51 | G41: =+F41*(1+$D41) | H41: =+G41*(1+$D41) | I41: =+H41*(1+$D41) | J41: =+I41*(1+$D41) | K41: =+J41*(1+$D41) | L41: =+K41*(1+$D41) | M41: =+L41*(1+$D41) | N41: =+M41*(1+$D41) | O41: =+N41*(1+$D41)
A42: MISCAD | C42: Misc. Admin Expenses | D42: =+Dashboard!$P$15 | E42: 0 | F42: =Dashboard!P52 | G42: =+F42*(1+$D42) | H42: =+G42*(1+$D42) | I42: =+H42*(1+$D42) | J42: =+I42*(1+$D42) | K42: =+J42*(1+$D42) | L42: =+K42*(1+$D42) | M42: =+L42*(1+$D42) | N42: =+M42*(1+$D42) | O42: =+N42*(1+$D42)
C43: Admin Expenses | E43: =SUM(E31:E42) | F43: =SUM(F31:F42) | G43: =SUM(G31:G42) | H43: =SUM(H31:H42) | I43: =SUM(I31:I42) | J43: =SUM(J31:J42) | K43: =SUM(K31:K42) | L43: =SUM(L31:L42) | ... O43: =SUM(O31:O42)
A45: ELEC | C45: Electric | D45: =+Dashboard!$P$15 | F45: =+Dashboard!V10 | G45: =+F45*(1+$D45) | H45: =+G45*(1+$D45) | I45: =+H45*(1+$D45) | J45: =+I45*(1+$D45) | K45: =+J45*(1+$D45) | L45: =+K45*(1+$D45) | M45: =+L45*(1+$D45) | N45: =+M45*(1+$D45) | O45: =+N45*(1+$D45)
A46: VAC | C46: Electric - Vacant | D46: =+Dashboard!$P$15 | F46: =+Dashboard!V11 | G46: =+F46*(1+$D46) | H46: =+G46*(1+$D46) | I46: =+H46*(1+$D46) | J46: =+I46*(1+$D46) | K46: =+J46*(1+$D46) | L46: =+K46*(1+$D46) | M46: =+L46*(1+$D46) | N46: =+M46*(1+$D46) | O46: =+N46*(1+$D46)
A47: WS | C47: Water & Sewer | D47: =+Dashboard!$P$15 | F47: =+Dashboard!V12 | G47: =+F47*(1+$D47) | H47: =+G47*(1+$D47) | I47: =+H47*(1+$D47) | J47: =+I47*(1+$D47) | K47: =+J47*(1+$D47) | L47: =+K47*(1+$D47) | M47: =+L47*(1+$D47) | N47: =+M47*(1+$D47) | O47: =+N47*(1+$D47)
A48: GAS | C48: Gas | D48: =+Dashboard!$P$15 | F48: =+Dashboard!V13 | G48: =+F48*(1+$D48) | H48: =+G48*(1+$D48) | I48: =+H48*(1+$D48) | J48: =+I48*(1+$D48) | K48: =+J48*(1+$D48) | L48: =+K48*(1+$D48) | M48: =+L48*(1+$D48) | N48: =+M48*(1+$D48) | O48: =+N48*(1+$D48)
A49: CABLE | C49: Cable | D49: =+Dashboard!$P$15 | F49: =+Dashboard!V14 | G49: =+F49*(1+$D49) | H49: =+G49*(1+$D49) | I49: =+H49*(1+$D49) | J49: =+I49*(1+$D49) | K49: =+J49*(1+$D49) | L49: =+K49*(1+$D49) | M49: =+L49*(1+$D49) | N49: =+M49*(1+$D49) | O49: =+N49*(1+$D49)
...

Sheet Scenario 1
C1: Underwriting Model Scenario 1
D3: Year | E3: =+'Scenario 0'!E3 | F3: =+'Scenario 0'!F3 | G3: =+'Scenario 0'!G3 | H3: =+'Scenario 0'!H3 | I3: =+'Scenario 0'!I3 | J3: =+'Scenario 0'!J3 | K3: =+'Scenario 0'!K3 | L3: =+'Scenario 0'!L3 | ... O3: =+'Scenario 0'!O3
C4: ='Unit Mix'!$P$3
C6: Income Statement | E6: =+'Scenario 0'!E6 | F6: =+'Scenario 0'!F6 | G6: =+'Scenario 0'!G6 | H6: =+'Scenario 0'!H6 | I6: =+'Scenario 0'!I6 | J6: =+'Scenario 0'!J6 | K6: =+'Scenario 0'!K6 | L6: =+'Scenario 0'!L6 | ... O6: =+'Scenario 0'!O6
C7: Gross Potential Income | E7: =+'Scenario 0'!$E$7 | F7: =+'Unit Mix'!U26 | G7: =+'Unit Mix'!U49 | H7: =+'Unit Mix'!U72 | I7: =+'Unit Mix'!U95 | J7: =+'Unit Mix'!U118 | K7: =+'Unit Mix'!U141 | L7: =+'Unit Mix'!U164 | M7: =+'Unit Mix'!U187 | N7: =+'Unit Mix'!U210 | O7: =+'Unit Mix'!U233
C8: Vacancy Factor | D8: =+Dashboard!$P$10 | E8: =+'Scenario 0'!$E$8 | F8: =+F7*$D$8 | G8: =+G7*$D$8 | H8: =+H7*$D$8 | I8: =+I7*$D$8 | J8: =+J7*$D$8 | K8: =+K7*$D$8 | L8: =+L7*$D$8 | M8: =+M7*$D$8 | ... O8: =+O7*$D$8
C9: Net Rental Income | E9: =+E7-E8 | F9: =+F7-F8 | G9: =+G7-G8 | H9: =+H7-H8 | I9: =+I7-I8 | J9: =+J7-J8 | K9: =+K7-K8 | L9: =+L7-L8 | ... O9: =+O7-O8
C11: Laundry and Other Income | D11: =+Dashboard!$P$14 | E11: =+'Scenario 0'!$E$11 | F11: =+Dashboard!$O$14 | G11: =+F11*(1+$D11) | H11: =+G11*(1+$D11) | I11: =+H11*(1+$D11) | J11: =+I11*(1+$D11) | K11: =+J11*(1+$D11) | L11: =+K11*(1+$D11) | M11: =+L11*(1+$D11) | N11: =+M11*(1+$D11) | O11: =+N11*(1+$D11)
C12: Total Gross Income | E12: =+SUM(E9:E11) | F12: =+SUM(F9:F11) | G12: =+SUM(G9:G11) | H12: =+SUM(H9:H11) | I12: =+SUM(I9:I11) | J12: =+SUM(J9:J11) | K12: =+SUM(K9:K11) | L12: =+SUM(L9:L11) | ... O12: =+SUM(O9:O11)
C13: Gross Income Growth | E13: -- | F13: =+F12/E12-1 | G13: =+G12/F12-1 | H13: =+H12/G12-1 | I13: =+I12/H12-1 | J13: =+J12/I12-1 | K13: =+K12/J12-1 | L13: =+L12/K12-1 | M13: =+M12/L12-1 | ... O13: =+O12/N12-1
C15: Opertating Expenses
A17: BAD
C18: Bad Debt | E18: =+'Scenario 0'!E18 | F18: =+'Scenario 0'!F18 | G18: =+'Scenario 0'!G18 | H18: =+'Scenario 0'!H18 | I18: =+'Scenario 0'!I18 | J18: =+'Scenario 0'!J18 | K18: =+'Scenario 0'!K18 | L18: =+'Scenario 0'!L18 | ... O18: =+'Scenario 0'!O18
A20: RES
A21: COM
C22: Total Replacement Reserves | E22: =+'Scenario 0'!E22 | F22: =+'Scenario 0'!F22 | G22: =+'Scenario 0'!G22 | H22: =+'Scenario 0'!H22 | I22: =+'Scenario 0'!I22 | J22: =+'Scenario 0'!J22 | K22: =+'Scenario 0'!K22 | L22: =+'Scenario 0'!L22 | ... O22: =+'Scenario 0'!O22
A24: MAN
A25: ASS
A26: PAY
A27: MAIT
C28: Payroll | E28: =+'Scenario 0'!E29 | F28: =+'Scenario 0'!F29 | G28: =+'Scenario 0'!G29 | H28: =+'Scenario 0'!H29 | I28: =+'Scenario 0'!I29 | J28: =+'Scenario 0'!J29 | K28: =+'Scenario 0'!K29 | L28: =+'Scenario 0'!L29 | ... O28: =+'Scenario 0'!O29
A30: MGMT
A31: LEGAL
A32: OFF
A33: TRAVEL
A34: AUD
A35: ADV
A36: TRAIN
A37: BANK
A38: BOOK
A39: PAYSERV
A40: UNIT
A41: MISCAD
C42: Admin Expenses | E42: =+'Scenario 0'!E43 | F42: =+'Scenario 0'!F43 | G42: =+'Scenario 0'!G43 | H42: =+'Scenario 0'!H43 | I42: =+'Scenario 0'!I43 | J42: =+'Scenario 0'!J43 | K42: =+'Scenario 0'!K43 | L42: =+'Scenario 0'!L43 | ... O42: =+'Scenario 0'!O43
A44: ELEC
A45: VAC
A46: WS
A47: GAS
A48: CABLE
A49: TRASH
...

Sheet Scenario 2
C1: Underwriting Model Scenario 2
D3: Year | E3: =+'Scenario 0'!E3 | F3: =+'Scenario 0'!F3 | G3: =+'Scenario 0'!G3 | H3: =+'Scenario 0'!H3 | I3: =+'Scenario 0'!I3 | J3: =+'Scenario 0'!J3 | K3: =+'Scenario 0'!K3 | L3: =+'Scenario 0'!L3 | ... O3: =+'Scenario 0'!O3
C4: ='Unit Mix'!$W$3
C6: Income Statement | E6: =+'Scenario 0'!E6 | F6: =+'Scenario 0'!F6 | G6: =+'Scenario 0'!G6 | H6: =+'Scenario 0'!H6 | I6: =+'Scenario 0'!I6 | J6: =+'Scenario 0'!J6 | K6: =+'Scenario 0'!K6 | L6: =+'Scenario 0'!L6 | ... O6: =+'Scenario 0'!O6
C7: Gross Potential Income | E7: =+'Scenario 0'!$E$7 | F7: =+'Unit Mix'!AB26 | G7: =+'Unit Mix'!AB49 | H7: =+'Unit Mix'!AB72 | I7: =+'Unit Mix'!AB95 | J7: =+'Unit Mix'!AB118 | K7: =+'Unit Mix'!AB141 | L7: =+'Unit Mix'!AB164 | M7: =+'Unit Mix'!AB187 | N7: =+'Unit Mix'!AB210 | O7: =+'Unit Mix'!AB233
C8: Vacancy Factor | D8: =+Dashboard!$P$10 | E8: =+'Scenario 0'!$E$8 | F8: =+F7*$D$8 | G8: =+G7*$D$8 | H8: =+H7*$D$8 | I8: =+I7*$D$8 | J8: =+J7*$D$8 | K8: =+K7*$D$8 | L8: =+L7*$D$8 | M8: =+M7*$D$8 | ... O8: =+O7*$D$8
C9: Net Rental Income | E9: =+E7-E8 | F9: =+F7-F8 | G9: =+G7-G8 | H9: =+H7-H8 | I9: =+I7-I8 | J9: =+J7-J8 | K9: =+K7-K8 | L9: =+L7-L8 | ... O9: =+O7-O8
C11: Laundry and Other Income | D11: =+Dashboard!$P$14 | E11: =+'Scenario 0'!$E$11 | F11: =+Dashboard!$O$14 | G11: =+F11*(1+$D11) | H11: =+G11*(1+$D11) | I11: =+H11*(1+$D11) | J11: =+I11*(1+$D11) | K11: =+J11*(1+$D11) | L11: =+K11*(1+$D11) | M11: =+L11*(1+$D11) | N11: =+M11*(1+$D11) | O11: =+N11*(1+$D11)
C12: Total Gross Income | E12: =+SUM(E9:E11) | F12: =+SUM(F9:F11) | G12: =+SUM(G9:G11) | H12: =+SUM(H9:H11) | I12: =+SUM(I9:I11) | J12: =+SUM(J9:J11) | K12: =+SUM(K9:K11) | L12: =+SUM(L9:L11) | ... O12: =+SUM(O9:O11)
C13: Gross Income Growth | E13: -- | F13: =+F12/E12-1 | G13: =+G12/F12-1 | H13: =+H12/G12-1 | I13: =+I12/H12-1 | J13: =+J12/I12-1 | K13: =+K12/J12-1 | L13: =+L12/K12-1 | M13: =+M12/L12-1 | ... O13: =+O12/N12-1
C15: Opertating Expenses
A17: BAD
C18: Bad Debt | E18: =+'Scenario 0'!E18 | F18: =+'Scenario 0'!F18 | G18: =+'Scenario 0'!G18 | H18: =+'Scenario 0'!H18 | I18: =+'Scenario 0'!I18 | J18: =+'Scenario 0'!J18 | K18: =+'Scenario 0'!K18 | L18: =+'Scenario 0'!L18 | ... O18: =+'Scenario 0'!O18
A20: RES
A21: COM
C22: Total Replacement Reserves | E22: =+'Scenario 0'!E22 | F22: =+'Scenario 0'!F22 | G22: =+'Scenario 0'!G22 | H22: =+'Scenario 0'!H22 | I22: =+'Scenario 0'!I22 | J22: =+'Scenario 0'!J22 | K22: =+'Scenario 0'!K22 | L22: =+'Scenario 0'!L22 | ... O22: =+'Scenario 0'!O22
A24: MAN
A25: ASS
A26: PAY
A27: MAIT
C28: Payroll | E28: =+'Scenario 0'!E29 | F28: =+'Scenario 0'!F29 | G28: =+'Scenario 0'!G29 | H28: =+'Scenario 0'!H29 | I28: =+'Scenario 0'!I29 | J28: =+'Scenario 0'!J29 | K28: =+'Scenario 0'!K29 | L28: =+'Scenario 0'!L29 | ... O28: =+'Scenario 0'!O29
A30: MGMT
A31: LEGAL
A32: OFF
A33: TRAVEL
A34: AUD
A35: ADV
A36: TRAIN
A37: BANK
A38: BOOK
A39: PAYSERV
A40: UNIT
A41: MISCAD
C42: Admin Expenses | E42: =+'Scenario 0'!E43 | F42: =+'Scenario 0'!F43 | G42: =+'Scenario 0'!G43 | H42: =+'Scenario 0'!H43 | I42: =+'Scenario 0'!I43 | J42: =+'Scenario 0'!J43 | K42: =+'Scenario 0'!K43 | L42: =+'Scenario 0'!L43 | ... O42: =+'Scenario 0'!O43
A44: ELEC
A45: VAC
A46: WS
A47: GAS
A48: CABLE
A49: TRASH
...

Sheet Scenario 3
C1: Underwriting Model Scenario 3
D3: Year | E3: =+'Scenario 0'!E3 | F3: =+'Scenario 0'!F3 | G3: =+'Scenario 0'!G3 | H3: =+'Scenario 0'!H3 | I3: =+'Scenario 0'!I3 | J3: =+'Scenario 0'!J3 | K3: =+'Scenario 0'!K3 | L3: =+'Scenario 0'!L3 | ... O3: =+'Scenario 0'!O3
C4: =+'Unit Mix'!AD3
C6: Income Statement | E6: =+'Scenario 0'!E6 | F6: =+'Scenario 0'!F6 | G6: =+'Scenario 0'!G6 | H6: =+'Scenario 0'!H6 | I6: =+'Scenario 0'!I6 | J6: =+'Scenario 0'!J6 | K6: =+'Scenario 0'!K6 | L6: =+'Scenario 0'!L6 | ... O6: =+'Scenario 0'!O6
C7: Gross Potential Income | E7: =+'Scenario 0'!$E$7 | F7: =+'Unit Mix'!AI26 | G7: =+'Unit Mix'!AI49 | H7: =+'Unit Mix'!AI72 | I7: =+'Unit Mix'!AI95 | J7: =+'Unit Mix'!AI118 | K7: =+'Unit Mix'!AI141 | L7: =+'Unit Mix'!AI164 | M7: =+'Unit Mix'!AI187 | N7: =+'Unit Mix'!AI210 | O7: =+'Unit Mix'!AI233
C8: Vacancy Factor | D8: =+Dashboard!$P$10 | E8: =+'Scenario 0'!$E$8 | F8: =+F7*$D$8 | G8: =+G7*$D$8 | H8: =+H7*$D$8 | I8: =+I7*$D$8 | J8: =+J7*$D$8 | K8: =+K7*$D$8 | L8: =+L7*$D$8 | M8: =+M7*$D$8 | ... O8: =+O7*$D$8
C9: Net Rental Income | E9: =+E7-E8 | F9: =+F7-F8 | G9: =+G7-G8 | H9: =+H7-H8 | I9: =+I7-I8 | J9: =+J7-J8 | K9: =+K7-K8 | L9: =+L7-L8 | ... O9: =+O7-O8
C11: Laundry and Other Income | D11: =+Dashboard!$P$14 | E11: =+'Scenario 0'!$E$11 | F11: =+Dashboard!$O$14 | G11: =+F11*(1+$D11) | H11: =+G11*(1+$D11) | I11: =+H11*(1+$D11) | J11: =+I11*(1+$D11) | K11: =+J11*(1+$D11) | L11: =+K11*(1+$D11) | M11: =+L11*(1+$D11) | N11: =+M11*(1+$D11) | O11: =+N11*(1+$D11)
C12: Total Gross Income | E12: =+SUM(E9:E11) | F12: =+SUM(F9:F11) | G12: =+SUM(G9:G11) | H12: =+SUM(H9:H11) | I12: =+SUM(I9:I11) | J12: =+SUM(J9:J11) | K12: =+SUM(K9:K11) | L12: =+SUM(L9:L11) | ... O12: =+SUM(O9:O11)
C13: Gross Income Growth | E13: -- | F13: =+F12/E12-1 | G13: =+G12/F12-1 | H13: =+H12/G12-1 | I13: =+I12/H12-1 | J13: =+J12/I12-1 | K13: =+K12/J12-1 | L13: =+L12/K12-1 | M13: =+M12/L12-1 | ... O13: =+O12/N12-1
C15: Opertating Expenses
A17: BAD
C18: Bad Debt | E18: =+'Scenario 0'!E18 | F18: =+'Scenario 0'!F18 | G18: =+'Scenario 0'!G18 | H18: =+'Scenario 0'!H18 | I18: =+'Scenario 0'!I18 | J18: =+'Scenario 0'!J18 | K18: =+'Scenario 0'!K18 | L18: =+'Scenario 0'!L18 | ... O18: =+'Scenario 0'!O18
A20: RES
A21: COM
C22: Total Replacement Reserves | E22: =+'Scenario 0'!E22 | F22: =+'Scenario 0'!F22 | G22: =+'Scenario 0'!G22 | H22: =+'Scenario 0'!H22 | I22: =+'Scenario 0'!I22 | J22: =+'Scenario 0'!J22 | K22: =+'Scenario 0'!K22 | L22: =+'Scenario 0'!L22 | ... O22: =+'Scenario 0'!O22
A24: MAN
A25: ASS
A26: PAY
A27: MAIT
C28: Payroll | E28: =+'Scenario 0'!E29 | F28: =+'Scenario 0'!F29 | G28: =+'Scenario 0'!G29 | H28: =+'Scenario 0'!H29 | I28: =+'Scenario 0'!I29 | J28: =+'Scenario 0'!J29 | K28: =+'Scenario 0'!K29 | L28: =+'Scenario 0'!L29 | ... O28: =+'Scenario 0'!O29
A30: MGMT
A31: LEGAL
A32: OFF
A33: TRAVEL
A34: AUD
A35: ADV
A36: TRAIN
A37: BANK
A38: BOOK
A39: PAYSERV
A40: UNIT
A41: MISCAD
C42: Admin Expenses | E42: =+'Scenario 0'!E43 | F42: =+'Scenario 0'!F43 | G42: =+'Scenario 0'!G43 | H42: =+'Scenario 0'!H43 | I42: =+'Scenario 0'!I43 | J42: =+'Scenario 0'!J43 | K42: =+'Scenario 0'!K43 | L42: =+'Scenario 0'!L43 | ... O42: =+'Scenario 0'!O43
A44: ELEC
A45: VAC
A46: WS
A47: GAS
A48: CABLE
A49: TRASH
...

Sheet Scenario 4
C1: Underwriting Model Scenario 4
D3: Year | E3: =+'Scenario 0'!E3 | F3: =+'Scenario 0'!F3 | G3: =+'Scenario 0'!G3 | H3: =+'Scenario 0'!H3 | I3: =+'Scenario 0'!I3 | J3: =+'Scenario 0'!J3 | K3: =+'Scenario 0'!K3 | L3: =+'Scenario 0'!L3 | ... O3: =+'Scenario 0'!O3
C4: =+'Unit Mix'!AK3
C6: Income Statement | E6: =+'Scenario 0'!E6 | F6: =+'Scenario 0'!F6 | G6: =+'Scenario 0'!G6 | H6: =+'Scenario 0'!H6 | I6: =+'Scenario 0'!I6 | J6: =+'Scenario 0'!J6 | K6: =+'Scenario 0'!K6 | L6: =+'Scenario 0'!L6 | ... O6: =+'Scenario 0'!O6
C7: Gross Potential Income | E7: =+'Scenario 0'!$E$7 | F7: =+'Unit Mix'!AP26 | G7: =+'Unit Mix'!AP49 | H7: =+'Unit Mix'!AP72 | I7: =+'Unit Mix'!AP95 | J7: =+'Unit Mix'!AP118 | K7: =+'Unit Mix'!AP141 | L7: =+'Unit Mix'!AP164 | M7: =+'Unit Mix'!AP187 | N7: =+'Unit Mix'!AP210 | O7: =+'Unit Mix'!AP233
C8: Vacancy Factor | D8: =+Dashboard!$P$10 | E8: =+'Scenario 0'!$E$8 | F8: =+F7*$D$8 | G8: =+G7*$D$8 | H8: =+H7*$D$8 | I8: =+I7*$D$8 | J8: =+J7*$D$8 | K8: =+K7*$D$8 | L8: =+L7*$D$8 | M8: =+M7*$D$8 | ... O8: =+O7*$D$8
C9: Net Rental Income | E9: =+E7-E8 | F9: =+F7-F8 | G9: =+G7-G8 | H9: =+H7-H8 | I9: =+I7-I8 | J9: =+J7-J8 | K9: =+K7-K8 | L9: =+L7-L8 | ... O9: =+O7-O8
C11: Laundry and Other Income | D11: =+Dashboard!$P$14 | E11: =+'Scenario 0'!$E$11 | F11: =+Dashboard!$O$14 | G11: =+F11*(1+$D11) | H11: =+G11*(1+$D11) | I11: =+H11*(1+$D11) | J11: =+I11*(1+$D11) | K11: =+J11*(1+$D11) | L11: =+K11*(1+$D11) | M11: =+L11*(1+$D11) | N11: =+M11*(1+$D11) | O11: =+N11*(1+$D11)
C12: Total Gross Income | E12: =+SUM(E9:E11) | F12: =+SUM(F9:F11) | G12: =+SUM(G9:G11) | H12: =+SUM(H9:H11) | I12: =+SUM(I9:I11) | J12: =+SUM(J9:J11) | K12: =+SUM(K9:K11) | L12: =+SUM(L9:L11) | ... O12: =+SUM(O9:O11)
C13: Gross Income Growth | E13: -- | F13: =+F12/E12-1 | G13: =+G12/F12-1 | H13: =+H12/G12-1 | I13: =+I12/H12-1 | J13: =+J12/I12-1 | K13: =+K12/J12-1 | L13: =+L12/K12-1 | M13: =+M12/L12-1 | ... O13: =+O12/N12-1
C15: Opertating Expenses
A17: BAD
C18: Bad Debt | E18: =+'Scenario 0'!E18 | F18: =+'Scenario 0'!F18 | G18: =+'Scenario 0'!G18 | H18: =+'Scenario 0'!H18 | I18: =+'Scenario 0'!I18 | J18: =+'Scenario 0'!J18 | K18: =+'Scenario 0'!K18 | L18: =+'Scenario 0'!L18 | ... O18: =+'Scenario 0'!O18
A20: RES
A21: COM
C22: Total Replacement Reserves | E22: =+'Scenario 0'!E22 | F22: =+'Scenario 0'!F22 | G22: =+'Scenario 0'!G22 | H22: =+'Scenario 0'!H22 | I22: =+'Scenario 0'!I22 | J22: =+'Scenario 0'!J22 | K22: =+'Scenario 0'!K22 | L22: =+'Scenario 0'!L22 | ... O22: =+'Scenario 0'!O22
A24: MAN
A25: ASS
A26: PAY
A27: MAIT
C28: Payroll | E28: =+'Scenario 0'!E29 | F28: =+'Scenario 0'!F29 | G28: =+'Scenario 0'!G29 | H28: =+'Scenario 0'!H29 | I28: =+'Scenario 0'!I29 | J28: =+'Scenario 0'!J29 | K28: =+'Scenario 0'!K29 | L28: =+'Scenario 0'!L29 | ... O28: =+'Scenario 0'!O29
A30: MGMT
A31: LEGAL
A32: OFF
A33: TRAVEL
A34: AUD
A35: ADV
A36: TRAIN
A37: BANK
A38: BOOK
A39: PAYSERV
A40: UNIT
A41: MISCAD
C42: Admin Expenses | E42: =+'Scenario 0'!E43 | F42: =+'Scenario 0'!F43 | G42: =+'Scenario 0'!G43 | H42: =+'Scenario 0'!H43 | I42: =+'Scenario 0'!I43 | J42: =+'Scenario 0'!J43 | K42: =+'Scenario 0'!K43 | L42: =+'Scenario 0'!L43 | ... O42: =+'Scenario 0'!O43
A44: ELEC
A45: VAC
A46: WS
A47: GAS
A48: CABLE
A49: TRASH
...

Sheet Rent Roll Calcs -->

Sheet Unit Mix
B3: Scenario 0 (No Change to Asset) | P3: Scenario 1 ( Max Current Vouchers) | W3: Scenario 2 (Max Net LIHTC) | AD3: Scenario 3 ( Max Current Vouchers + NET LIHTC) | AK3: Scenario 4 (Max Net LIHTC)
B5: Year 1 | P5: =+$B5 | W5: =+$B5 | AD5: =+$B5 | AK5: =+$B5
B6: Unit Type | C6: AMI / S8 | D6: # of Units | E6: Avg. SF | F6: Avg. Utilities | G6: Avg. Max LITHC | H6: Net LIHTC | I6: Avg. Max FMR | J6: Net FMR | K6: CoStar Rent | L6: Gross Rent | M6: Avg. Current Rent | N6: Yrly. Gross Income (Net Rent) | P6: Unit Type | Q6: AMI / S8 | R6: # of Units | S6: Avg. SF | T6: Avg. Utilities | U6: Max Current Vouchers | W6: Unit Type | X6: AMI / S8 | Y6: # of Units | Z6: Avg. SF | AA6: Avg. Utilities | AB6: Max NET LIHTC | AD6: Unit Type | AE6: AMI / S8 | AF6: # of Units | AG6: Avg. SF | AH6: Avg. Utilities | AI6: Max Current Vouchers + NET LIHTC | AK6: Unit Type | AL6: AMI / S8 | AM6: # of Units | AN6: Avg. SF | AO6: Avg. Utilities | AP6: Max Net LIHTC / Voucher Floor
B7: ='Rent Roll'!C13 | C7: ='Rent Roll'!D13 | D7: ='Rent Roll'!E13 | E7: ='Rent Roll'!F13 | F7: ='Rent Roll'!K13 | G7: ='Rent Roll'!M13 | H7: =+G7-F7 | I7: ='Rent Roll'!O13 | J7: =I7-F7 | K7: ='Rent Roll'!G13 | L7: ='Rent Roll'!L13 | M7: ='Rent Roll'!J13 | N7: =((M7*D7)*12) | P7: =B7 | Q7: =C7 | R7: =D7 | S7: =E7 | T7: =F7 | U7: =((M7*R7)*12) | W7: =B7 | X7: =C7 | Y7: =D7 | Z7: =E7 | AA7: =F7 | AB7: =((H7*Y7)*12) | AD7: =B7 | AE7: =C7 | AF7: =D7 | AG7: =E7 | AH7: =F7 | AI7: =+MAX(U7,AB7) | AK7: =B7 | AL7: =C7 | AM7: =D7 | AN7: =E7 | AO7: =F7 | AP7: =IF(G7>0,MAX(U7,AB7),N7)
B8: ='Rent Roll'!C14 | C8: ='Rent Roll'!D14 | D8: ='Rent Roll'!E14 | E8: ='Rent Roll'!F14 | F8: ='Rent Roll'!K14 | G8: ='Rent Roll'!M14 | H8: =+G8-F8 | I8: ='Rent Roll'!O14 | J8: =I8-F8 | K8: ='Rent Roll'!G14 | L8: ='Rent Roll'!L14 | M8: ='Rent Roll'!J14 | N8: =((M8*D8)*12) | P8: =B8 | Q8: =C8 | R8: =D8 | S8: =E8 | T8: =F8 | U8: =((M8*R8)*12) | W8: =B8 | X8: =C8 | Y8: =D8 | Z8: =E8 | AA8: =F8 | AB8: =((H8*Y8)*12) | AD8: =B8 | AE8: =C8 | AF8: =D8 | AG8: =E8 | AH8: =F8 | AI8: =+MAX(U8,AB8) | AK8: =B8 | AL8: =C8 | AM8: =D8 | AN8: =E8 | AO8: =F8 | AP8: =IF(G8>0,MAX(U8,AB8),N8)
B9: ='Rent Roll'!C15 | C9: ='Rent Roll'!D15 | D9: ='Rent Roll'!E15 | E9: ='Rent Roll'!F15 | F9: ='Rent Roll'!K15 | G9: ='Rent Roll'!M15 | H9: =+G9-F9 | I9: ='Rent Roll'!O15 | J9: =I9-F9 | K9: ='Rent Roll'!G15 | L9: ='Rent Roll'!L15 | M9: ='Rent Roll'!J15 | N9: =((M9*D9)*12) | P9: =B9 | Q9: =C9 | R9: =D9 | S9: =E9 | T9: =F9 | U9: =((M9*R9)*12) | W9: =B9 | X9: =C9 | Y9: =D9 | Z9: =E9 | AA9: =F9 | AB9: =((H9*Y9)*12) | AD9: =B9 | AE9: =C9 | AF9: =D9 | AG9: =E9 | AH9: =F9 | AI9: =+MAX(U9,AB9) | AK9: =B9 | AL9: =C9 | AM9: =D9 | AN9: =E9 | AO9: =F9 | AP9: =IF(G9>0,MAX(U9,AB9),N9)
B10: ='Rent Roll'!C16 | C10: ='Rent Roll'!D16 | D10: ='Rent Roll'!E16 | E10: ='Rent Roll'!F16 | F10: ='Rent Roll'!K16 | G10: ='Rent Roll'!M16 | H10: =+G10-F10 | I10: ='Rent Roll'!O16 | J10: =I10-F10 | K10: ='Rent Roll'!G16 | L10: ='Rent Roll'!L16 | M10: ='Rent Roll'!J16 | N10: =((M10*D10)*12) | P10: =B10 | Q10: =C10 | R10: =D10 | S10: =E10 | T10: =F10 | U10: =((M10*R10)*12) | W10: =B10 | X10: =C10 | Y10: =D10 | Z10: =E10 | AA10: =F10 | AB10: =((H10*Y10)*12) | AD10: =B10 | AE10: =C10 | AF10: =D10 | AG10: =E10 | AH10: =F10 | AI10: =+MAX(U10,AB10) | AK10: =B10 | AL10: =C10 | AM10: =D10 | AN10: =E10 | AO10: =F10 | AP10: =IF(G10>0,MAX(U10,AB10),N10)
B11: ='Rent Roll'!C17 | C11: ='Rent Roll'!D17 | D11: ='Rent Roll'!E17 | E11: ='Rent Roll'!F17 | F11: ='Rent Roll'!K17 | G11: ='Rent Roll'!M17 | H11: =+G11-F11 | I11: ='Rent Roll'!O17 | J11: =I11-F11 | K11: ='Rent Roll'!G17 | L11: ='Rent Roll'!L17 | M11: ='Rent Roll'!J17 | N11: =((M11*D11)*12) | P11: =B11 | Q11: =C11 | R11: =D11 | S11: =E11 | T11: =F11 | U11: =((M11*R11)*12) | W11: =B11 | X11: =C11 | Y11: =D11 | Z11: =E11 | AA11: =F11 | AB11: =((H11*Y11)*12) | AD11: =B11 | AE11: =C11 | AF11: =D11 | AG11: =E11 | AH11: =F11 | AI11: =+MAX(U11,AB11) | AK11: =B11 | AL11: =C11 | AM11: =D11 | AN11: =E11 | AO11: =F11 | AP11: =IF(G11>0,MAX(U11,AB11),N11)
B12: ='Rent Roll'!C18 | C12: ='Rent Roll'!D18 | D12: ='Rent Roll'!E18 | E12: ='Rent Roll'!F18 | F12: ='Rent Roll'!K18 | G12: ='Rent Roll'!M18 | H12: =+G12-F12 | I12: ='Rent Roll'!O18 | J12: =I12-F12 | K12: ='Rent Roll'!G18 | L12: ='Rent Roll'!L18 | M12: ='Rent Roll'!J18 | N12: =((M12*D12)*12) | P12: =B12 | Q12: =C12 | R12: =D12 | S12: =E12 | T12: =F12 | U12: =((M12*R12)*12) | W12: =B12 | X12: =C12 | Y12: =D12 | Z12: =E12 | AA12: =F12 | AB12: =((H12*Y12)*12) | AD12: =B12 | AE12: =C12 | AF12: =D12 | AG12: =E12 | AH12: =F12 | AI12: =+MAX(U12,AB12) | AK12: =B12 | AL12: =C12 | AM12: =D12 | AN12: =E12 | AO12: =F12 | AP12: =IF(G12>0,MAX(U12,AB12),N12)
B13: ='Rent Roll'!C19 | C13: ='Rent Roll'!D19 | D13: ='Rent Roll'!E19 | E13: ='Rent Roll'!F19 | F13: ='Rent Roll'!K19 | G13: ='Rent Roll'!M19 | H13: =+G13-F13 | I13: ='Rent Roll'!O19 | J13: =I13-F13 | K13: ='Rent Roll'!G19 | L13: ='Rent Roll'!L19 | M13: ='Rent Roll'!J19 | N13: =((M13*D13)*12) | P13: =B13 | Q13: =C13 | R13: =D13 | S13: =E13 | T13: =F13 | U13: =((M13*R13)*12) | W13: =B13 | X13: =C13 | Y13: =D13 | Z13: =E13 | AA13: =F13 | AB13: =((H13*Y13)*12) | AD13: =B13 | AE13: =C13 | AF13: =D13 | AG13: =E13 | AH13: =F13 | AI13: =+MAX(U13,AB13) | AK13: =B13 | AL13: =C13 | AM13: =D13 | AN13: =E13 | AO13: =F13 | AP13: =IF(G13>0,MAX(U13,AB13),N13)
B14: ='Rent Roll'!C20 | C14: ='Rent Roll'!D20 | D14: ='Rent Roll'!E20 | E14: ='Rent Roll'!F20 | F14: ='Rent Roll'!K20 | G14: ='Rent Roll'!M20 | H14: =+G14-F14 | I14: ='Rent Roll'!O20 | J14: =I14-F14 | K14: ='Rent Roll'!G20 | L14: ='Rent Roll'!L20 | M14: ='Rent Roll'!J20 | N14: =((M14*D14)*12) | P14: =B14 | Q14: =C14 | R14: =D14 | S14: =E14 | T14: =F14 | U14: =((M14*R14)*12) | W14: =B14 | X14: =C14 | Y14: =D14 | Z14: =E14 | AA14: =F14 | AB14: =((H14*Y14)*12) | AD14: =B14 | AE14: =C14 | AF14: =D14 | AG14: =E14 | AH14: =F14 | AI14: =+MAX(U14,AB14) | AK14: =B14 | AL14: =C14 | AM14: =D14 | AN14: =E14 | AO14: =F14 | AP14: =IF(G14>0,MAX(U14,AB14),N14)
B15: ='Rent Roll'!C21 | C15: ='Rent Roll'!D21 | D15: ='Rent Roll'!E21 | E15: ='Rent Roll'!F21 | F15: ='Rent Roll'!K21 | G15: ='Rent Roll'!M21 | H15: =+G15-F15 | I15: ='Rent Roll'!O21 | J15: =I15-F15 | K15: ='Rent Roll'!G21 | L15: ='Rent Roll'!L21 | M15: ='Rent Roll'!J21 | N15: =((M15*D15)*12) | P15: =B15 | Q15: =C15 | R15: =D15 | S15: =E15 | T15: =F15 | U15: =((M15*R15)*12) | W15: =B15 | X15: =C15 | Y15: =D15 | Z15: =E15 | AA15: =F15 | AB15: =((H15*Y15)*12) | AD15: =B15 | AE15: =C15 | AF15: =D15 | AG15: =E15 | AH15: =F15 | AI15: =+MAX(U15,AB15) | AK15: =B15 | AL15: =C15 | AM15: =D15 | AN15: =E15 | AO15: =F15 | AP15: =IF(G15>0,MAX(U15,AB15),N15)
B16: ='Rent Roll'!C22 | C16: ='Rent Roll'!D22 | D16: ='Rent Roll'!E22 | E16: ='Rent Roll'!F22 | F16: ='Rent Roll'!K22 | G16: ='Rent Roll'!M22 | H16: =+G16-F16 | I16: ='Rent Roll'!O22 | J16: =I16-F16 | K16: ='Rent Roll'!G22 | L16: ='Rent Roll'!L22 | M16: ='Rent Roll'!J22 | N16: =((M16*D16)*12) | P16: =B16 | Q16: =C16 | R16: =D16 | S16: =E16 | T16: =F16 | U16: =((M16*R16)*12) | W16: =B16 | X16: =C16 | Y16: =D16 | Z16: =E16 | AA16: =F16 | AB16: =((H16*Y16)*12) | AD16: =B16 | AE16: =C16 | AF16: =D16 | AG16: =E16 | AH16: =F16 | AI16: =+MAX(U16,AB16) | AK16: =B16 | AL16: =C16 | AM16: =D16 | AN16: =E16 | AO16: =F16 | AP16: =IF(G16>0,MAX(U16,AB16),N16)
B17: ='Rent Roll'!C23 | C17: ='Rent Roll'!D23 | D17: ='Rent Roll'!E23 | E17: ='Rent Roll'!F23 | F17: ='Rent Roll'!K23 | G17: ='Rent Roll'!M23 | H17: =+G17-F17 | I17: ='Rent Roll'!O23 | J17: =I17-F17 | K17: ='Rent Roll'!G23 | L17: ='Rent Roll'!L23 | M17: ='Rent Roll'!J23 | N17: =((M17*D17)*12) | P17: =B17 | Q17: =C17 | R17: =D17 | S17: =E17 | T17: =F17 | U17: =((M17*R17)*12) | W17: =B17 | X17: =C17 | Y17: =D17 | Z17: =E17 | AA17: =F17 | AB17: =((H17*Y17)*12) | AD17: =B17 | AE17: =C17 | AF17: =D17 | AG17: =E17 | AH17: =F17 | AI17: =+MAX(U17,AB17) | AK17: =B17 | AL17: =C17 | AM17: =D17 | AN17: =E17 | AO17: =F17 | AP17: =IF(G17>0,MAX(U17,AB17),N17)
B18: ='Rent Roll'!C24 | C18: ='Rent Roll'!D24 | D18: ='Rent Roll'!E24 | E18: ='Rent Roll'!F24 | F18: ='Rent Roll'!K24 | G18: ='Rent Roll'!M24 | H18: =+G18-F18 | I18: ='Rent Roll'!O24 | J18: =I18-F18 | K18: ='Rent Roll'!G24 | L18: ='Rent Roll'!L24 | M18: ='Rent Roll'!J24 | N18: =((M18*D18)*12) | P18: =B18 | Q18: =C18 | R18: =D18 | S18: =E18 | T18: =F18 | U18: =((M18*R18)*12) | W18: =B18 | X18: =C18 | Y18: =D18 | Z18: =E18 | AA18: =F18 | AB18: =((H18*Y18)*12) | AD18: =B18 | AE18: =C18 | AF18: =D18 | AG18: =E18 | AH18: =F18 | AI18: =+MAX(U18,AB18) | AK18: =B18 | AL18: =C18 | AM18: =D18 | AN18: =E18 | AO18: =F18 | AP18: =IF(G18>0,MAX(U18,AB18),N18)
... B25: ='Rent Roll'!C31 | C25: ='Rent Roll'!D31 | D25: ='Rent Roll'!E31 | E25: ='Rent Roll'!F31 | F25: ='Rent Roll'!K31 | G25: ='Rent Roll'!M31 | H25: =+G25-F25 | I25: ='Rent Roll'!O31 | J25: =I25-F25 | K25: ='Rent Roll'!G31 | L25: ='Rent Roll'!L31 | M25: ='Rent Roll'!J31 | N25: =((M25*D25)*12) | P25: =B25 | Q25: =C25 | R25: =D25 | S25: =E25 | T25: =F25 | U25: =((M25*R25)*12) | W25: =B25 | X25: =C25 | Y25: =D25 | Z25: =E25 | AA25: =F25 | AB25: =((H25*Y25)*12) | AD25: =B25 | AE25: =C25 | AF25: =D25 | AG25: =E25 | AH25: =F25 | AI25: =+MAX(U25,AB25) | AK25: =B25 | AL25: =C25 | AM25: =D25 | AN25: =E25 | AO25: =F25 | AP25: =IF(G25>0,MAX(U25,AB25),N25)
B26: Total (Pre-Vacancy) | D26: =SUM(D7:D25) | E26: =+SUMPRODUCT(E7:E25,$D7:$D25) | F26: =+SUMPRODUCT(F7:F25,$D7:$D25) | G26: =+SUMPRODUCT(G7:G25,$D7:$D25) | H26: =+SUMPRODUCT(H7:H25,$D7:$D25) | I26: =+SUMPRODUCT(I7:I25,$D7:$D25) | J26: =+SUMPRODUCT(J7:J25,$D7:$D25) | K26: =+SUMPRODUCT(K7:K25,$D7:$D25) | L26: =+SUMPRODUCT(L7:L25,$D7:$D25) | M26: =+SUMPRODUCT(M7:M25,$D7:$D25) | N26: =SUM(N7:N25) | P26: Total (Pre-Vacancy) | R26: =SUM(R7:R25) | S26: =+SUMPRODUCT(S7:S25,$R7:$R25) | T26: =+SUMPRODUCT(T7:T25,$R7:$R25) | U26: =SUM(U7:U25) | W26: Total (Pre-Vacancy) | Y26: =SUM(Y7:Y25) | Z26: =+SUMPRODUCT(Z7:Z25,$Y7:$Y25) | AA26: =+SUMPRODUCT(AA7:AA25,$Y7:$Y25) | AB26: =SUM(AB7:AB25) | AD26: Total (Pre-Vacancy) | AF26: =SUM(AF7:AF25) | AG26: =+SUMPRODUCT(AG7:AG25,$AF7:$AF25) | AH26: =+SUMPRODUCT(AH7:AH25,$AF7:$AF25) | AI26: =SUM(AI7:AI25) | AK26: Total (Pre-Vacancy) | AM26: =SUM(AF7:AF25) | AN26: =+SUMPRODUCT(AG7:AG25,$AF7:$AF25) | AO26: =+SUMPRODUCT(AH7:AH25,$AF7:$AF25) | AP26: =SUM(AP7:AP25)
B28: Year 2 | P28: =+$B28 | W28: =+$B28 | AD28: =+$B28 | AK28: =+$B28
B29: Unit Type | C29: AMI / S8 | D29: # of Units | E29: Avg. SF | F29: Avg. Utilities | G29: Avg. Max LITHC | H29: Net LIHTC | I29: Avg. Max FMR | J29: Net FMR | K29: =+K6 | L29: Gross Rent | M29: Avg. Current Rent | N29: Yrly. Gross Income (Net Rent) | P29: Unit Type | Q29: AMI / S8 | R29: # of Units | S29: Avg. SF | T29: Avg. Utilities | U29: Max Current Vouchers | W29: Unit Type | X29: AMI / S8 | Y29: # of Units | Z29: Avg. SF | AA29: Avg. Utilities | AB29: Max NET LIHTC | AD29: Unit Type | AE29: AMI / S8 | AF29: # of Units | AG29: Avg. SF | AH29: Avg. Utilities | AI29: Max Current Vouchers + NET LIHTC | AK29: Unit Type | AL29: AMI / S8 | AM29: # of Units | AN29: Avg. SF | AO29: Avg. Utilities | AP29: Max Current Vouchers + NET LIHTC
B30: =B7 | C30: =C7 | D30: =$D7 | E30: =E7 | F30: =F7*(1+Dashboard!$P$12) | G30: =G7*(1+Dashboard!$P$11) | H30: =+G30-F30 | I30: =I7*(1+Dashboard!$P$11) | J30: =I30-F30 | K30: =K7*(1+Dashboard!$P$11) | L30: =M30+F30 | M30: =M7*(1+Dashboard!$P$11) | N30: =((M30*D30)*12) | P30: =B30 | Q30: =C30 | R30: =D30 | S30: =E30 | T30: =F30 | U30: =((M30*R30)*12) | W30: =B30 | X30: =C30 | Y30: =D30 | Z30: =E30 | AA30: =F30 | AB30: =((H30*Y30)*12) | AD30: =B30 | AE30: =C30 | AF30: =D30 | AG30: =E30 | AH30: =F30 | AI30: =+MAX(U30,AB30) | AK30: =B30 | AL30: =C30 | AM30: =D30 | AN30: =E30 | AO30: =F30 | AP30: =IF(G30>0,MAX(U30,AB30),N30)
B31: =B8 | C31: =C8 | D31: =$D8 | E31: =E8 | F31: =F8*(1+Dashboard!$P$12) | G31: =G8*(1+Dashboard!$P$11) | H31: =+G31-F31 | I31: =I8*(1+Dashboard!$P$11) | J31: =I31-F31 | K31: =K8*(1+Dashboard!$P$11) | L31: =M31+F31 | M31: =M8*(1+Dashboard!$P$11) | N31: =((M31*D31)*12) | P31: =B31 | Q31: =C31 | R31: =D31 | S31: =E31 | T31: =F31 | U31: =((M31*R31)*12) | W31: =B31 | X31: =C31 | Y31: =D31 | Z31: =E31 | AA31: =F31 | AB31: =((H31*Y31)*12) | AD31: =B31 | AE31: =C31 | AF31: =D31 | AG31: =E31 | AH31: =F31 | AI31: =+MAX(U31,AB31) | AK31: =B31 | AL31: =C31 | AM31: =D31 | AN31: =E31 | AO31: =F31 | AP31: =IF(G31>0,MAX(U31,AB31),N31)
B32: =B9 | C32: =C9 | D32: =$D9 | E32: =E9 | F32: =F9*(1+Dashboard!$P$12) | G32: =G9*(1+Dashboard!$P$11) | H32: =+G32-F32 | I32: =I9*(1+Dashboard!$P$11) | J32: =I32-F32 | K32: =K9*(1+Dashboard!$P$11) | L32: =M32+F32 | M32: =M9*(1+Dashboard!$P$11) | N32: =((M32*D32)*12) | P32: =B32 | Q32: =C32 | R32: =D32 | S32: =E32 | T32: =F32 | U32: =((M32*R32)*12) | W32: =B32 | X32: =C32 | Y32: =D32 | Z32: =E32 | AA32: =F32 | AB32: =((H32*Y32)*12) | AD32: =B32 | AE32: =C32 | AF32: =D32 | AG32: =E32 | AH32: =F32 | AI32: =+MAX(U32,AB32) | AK32: =B32 | AL32: =C32 | AM32: =D32 | AN32: =E32 | AO32: =F32 | AP32: =IF(G32>0,MAX(U32,AB32),N32)
B33: =B10 | C33: =C10 | D33: =$D10 | E33: =E10 | F33: =F10*(1+Dashboard!$P$12) | G33: =G10*(1+Dashboard!$P$11) | H33: =+G33-F33 | I33: =I10*(1+Dashboard!$P$11) | J33: =I33-F33 | K33: =K10*(1+Dashboard!$P$11) | L33: =M33+F33 | M33: =M10*(1+Dashboard!$P$11) | N33: =((M33*D33)*12) | P33: =B33 | Q33: =C33 | R33: =D33 | S33: =E33 | T33: =F33 | U33: =((M33*R33)*12) | W33: =B33 | X33: =C33 | Y33: =D33 | Z33: =E33 | AA33: =F33 | AB33: =((H33*Y33)*12) | AD33: =B33 | AE33: =C33 | AF33: =D33 | AG33: =E33 | AH33: =F33 | AI33: =+MAX(U33,AB33) | AK33: =B33 | AL33: =C33 | AM33: =D33 | AN33: =E33 | AO33: =F33 | AP33: =IF(G33>0,MAX(U33,AB33),N33)
B34: =B11 | C34: =C11 | D34: =$D11 | E34: =E11 | F34: =F11*(1+Dashboard!$P$12) | G34: =G11*(1+Dashboard!$P$11) | H34: =+G34-F34 | I34: =I11*(1+Dashboard!$P$11) | J34: =I34-F34 | K34: =K11*(1+Dashboard!$P$11) | L34: =M34+F34 | M34: =M11*(1+Dashboard!$P$11) | N34: =((M34*D34)*12) | P34: =B34 | Q34: =C34 | R34: =D34 | S34: =E34 | T34: =F34 | U34: =((M34*R34)*12) | W34: =B34 | X34: =C34 | Y34: =D34 | Z34: =E34 | AA34: =F34 | AB34: =((H34*Y34)*12) | AD34: =B34 | AE34: =C34 | AF34: =D34 | AG34: =E34 | AH34: =F34 | AI34: =+MAX(U34,AB34) | AK34: =B34 | AL34: =C34 | AM34: =D34 | AN34: =E34 | AO34: =F34 | AP34: =IF(G34>0,MAX(U34,AB34),N34)
B35: =B12 | C35: =C12 | D35: =$D12 | E35: =E12 | F35: =F12*(1+Dashboard!$P$12) | G35: =G12*(1+Dashboard!$P$11) | H35: =+G35-F35 | I35: =I12*(1+Dashboard!$P$11) | J35: =I35-F35 | K35: =K12*(1+Dashboard!$P$11) | L35: =M35+F35 | M35: =M12*(1+Dashboard!$P$11) | N35: =((M35*D35)*12) | P35: =B35 | Q35: =C35 | R35: =D35 | S35: =E35 | T35: =F35 | U35: =((M35*R35)*12) | W35: =B35 | X35: =C35 | Y35: =D35 | Z35: =E35 | AA35: =F35 | AB35: =((H35*Y35)*12) | AD35: =B35 | AE35: =C35 | AF35: =D35 | AG35: =E35 | AH35: =F35 | AI35: =+MAX(U35,AB35) | AK35: =B35 | AL35: =C35 | AM35: =D35 | AN35: =E35 | AO35: =F35 | AP35: =IF(G35>0,MAX(U35,AB35),N35)
B36: =B13 | C36: =C13 | D36: =$D13 | E36: =E13 | F36: =F13*(1+Dashboard!$P$12) | G36: =G13*(1+Dashboard!$P$11) | H36: =+G36-F36 | I36: =I13*(1+Dashboard!$P$11) | J36: =I36-F36 | K36: =K13*(1+Dashboard!$P$11) | L36: =M36+F36 | M36: =M13*(1+Dashboard!$P$11) | N36: =((M36*D36)*12) | P36: =B36 | Q36: =C36 | R36: =D36 | S36: =E36 | T36: =F36 | U36: =((M36*R36)*12) | W36: =B36 | X36: =C36 | Y36: =D36 | Z36: =E36 | AA36: =F36 | AB36: =((H36*Y36)*12) | AD36: =B36 | AE36: =C36 | AF36: =D36 | AG36: =E36 | AH36: =F36 | AI36: =+MAX(U36,AB36) | AK36: =B36 | AL36: =C36 | AM36: =D36 | AN36: =E36 | AO36: =F36 | AP36: =IF(G36>0,MAX(U36,AB36),N36)
B37: =B14 | C37: =C14 | D37: =$D14 | E37: =E14 | F37: =F14*(1+Dashboard!$P$12) | G37: =G14*(1+Dashboard!$P$11) | H37: =+G37-F37 | I37: =I14*(1+Dashboard!$P$11) | J37: =I37-F37 | K37: =K14*(1+Dashboard!$P$11) | L37: =M37+F37 | M37: =M14*(1+Dashboard!$P$11) | N37: =((M37*D37)*12) | P37: =B37 | Q37: =C37 | R37: =D37 | S37: =E37 | T37: =F37 | U37: =((M37*R37)*12) | W37: =B37 | X37: =C37 | Y37: =D37 | Z37: =E37 | AA37: =F37 | AB37: =((H37*Y37)*12) | AD37: =B37 | AE37: =C37 | AF37: =D37 | AG37: =E37 | AH37: =F37 | AI37: =+MAX(U37,AB37) | AK37: =B37 | AL37: =C37 | AM37: =D37 | AN37: =E37 | AO37: =F37 | AP37: =IF(G37>0,MAX(U37,AB37),N37)
B38: =B15 | C38: =C15 | D38: =$D15 | E38: =E15 | F38: =F15*(1+Dashboard!$P$12) | G38: =G15*(1+Dashboard!$P$11) | H38: =+G38-F38 | I38: =I15*(1+Dashboard!$P$11) | J38: =I38-F38 | K38: =K15*(1+Dashboard!$P$11) | L38: =M38+F38 | M38: =M15*(1+Dashboard!$P$11) | N38: =((M38*D38)*12) | P38: =B38 | Q38: =C38 | R38: =D38 | S38: =E38 | T38: =F38 | U38: =((M38*R38)*12) | W38: =B38 | X38: =C38 | Y38: =D38 | Z38: =E38 | AA38: =F38 | AB38: =((H38*Y38)*12) | AD38: =B38 | AE38: =C38 | AF38: =D38 | AG38: =E38 | AH38: =F38 | AI38: =+MAX(U38,AB38) | AK38: =B38 | AL38: =C38 | AM38: =D38 | AN38: =E38 | AO38: =F38 | AP38: =IF(G38>0,MAX(U38,AB38),N38)
B39: =B16 | C39: =C16 | D39: =$D16 | E39: =E16 | F39: =F16*(1+Dashboard!$P$12) | G39: =G16*(1+Dashboard!$P$11) | H39: =+G39-F39 | I39: =I16*(1+Dashboard!$P$11) | J39: =I39-F39 | K39: =K16*(1+Dashboard!$P$11) | L39: =M39+F39 | M39: =M16*(1+Dashboard!$P$11) | N39: =((M39*D39)*12) | P39: =B39 | Q39: =C39 | R39: =D39 | S39: =E39 | T39: =F39 | U39: =((M39*R39)*12) | W39: =B39 | X39: =C39 | Y39: =D39 | Z39: =E39 | AA39: =F39 | AB39: =((H39*Y39)*12) | AD39: =B39 | AE39: =C39 | AF39: =D39 | AG39: =E39 | AH39: =F39 | AI39: =+MAX(U39,AB39) | AK39: =B39 | AL39: =C39 | AM39: =D39 | AN39: =E39 | AO39: =F39 | AP39: =IF(G39>0,MAX(U39,AB39),N39)
B40: =B17 | C40: =C17 | D40: =$D17 | E40: =E17 | F40: =F17*(1+Dashboard!$P$12) | G40: =G17*(1+Dashboard!$P$11) | H40: =+G40-F40 | I40: =I17*(1+Dashboard!$P$11) | J40: =I40-F40 | K40: =K17*(1+Dashboard!$P$11) | L40: =M40+F40 | M40: =M17*(1+Dashboard!$P$11) | N40: =((M40*D40)*12) | P40: =B40 | Q40: =C40 | R40: =D40 | S40: =E40 | T40: =F40 | U40: =((M40*R40)*12) | W40: =B40 | X40: =C40 | Y40: =D40 | Z40: =E40 | AA40: =F40 | AB40: =((H40*Y40)*12) | AD40: =B40 | AE40: =C40 | AF40: =D40 | AG40: =E40 | AH40: =F40 | AI40: =+MAX(U40,AB40) | AK40: =B40 | AL40: =C40 | AM40: =D40 | AN40: =E40 | AO40: =F40 | AP40: =IF(G40>0,MAX(U40,AB40),N40)
B41: =B18 | C41: =C18 | D41: =$D18 | E41: =E18 | F41: =F18*(1+Dashboard!$P$12) | G41: =G18*(1+Dashboard!$P$11) | H41: =+G41-F41 | I41: =I18*(1+Dashboard!$P$11) | J41: =I41-F41 | K41: =K18*(1+Dashboard!$P$11) | L41: =M41+F41 | M41: =M18*(1+Dashboard!$P$11) | N41: =((M41*D41)*12) | P41: =B41 | Q41: =C41 | R41: =D41 | S41: =E41 | T41: =F41 | U41: =((M41*R41)*12) | W41: =B41 | X41: =C41 | Y41: =D41 | Z41: =E41 | AA41: =F41 | AB41: =((H41*Y41)*12) | AD41: =B41 | AE41: =C41 | AF41: =D41 | AG41: =E41 | AH41: =F41 | AI41: =+MAX(U41,AB41) | AK41: =B41 | AL41: =C41 | AM41: =D41 | AN41: =E41 | AO41: =F41 | AP41: =IF(G41>0,MAX(U41,AB41),N41)
... B48: =B25 | C48: =C25 | D48: =$D25 | E48: =E25 | F48: =F25*(1+Dashboard!$P$12) | G48: =G25*(1+Dashboard!$P$11) | H48: =+G48-F48 | I48: =I25*(1+Dashboard!$P$11) | J48: =I48-F48 | K48: =K25*(1+Dashboard!$P$11) | L48: =M48+F48 | M48: =M25*(1+Dashboard!$P$11) | N48: =((M48*D48)*12) | P48: =B48 | Q48: =C48 | R48: =D48 | S48: =E48 | T48: =F48 | U48: =((M48*R48)*12) | W48: =B48 | X48: =C48 | Y48: =D48 | Z48: =E48 | AA48: =F48 | AB48: =((H48*Y48)*12) | AD48: =B48 | AE48: =C48 | AF48: =D48 | AG48: =E48 | AH48: =F48 | AI48: =+MAX(U48,AB48) | AK48: =B48 | AL48: =C48 | AM48: =D48 | AN48: =E48 | AO48: =F48 | AP48: =IF(G48>0,MAX(U48,AB48),N48)
B49: Total (Pre-Vacancy) | D49: =SUM(D30:D48) | E49: =+SUMPRODUCT(E30:E48,$D30:$D48) | F49: =+SUMPRODUCT(F30:F48,$D30:$D48) | G49: =+SUMPRODUCT(G30:G48,$D30:$D48) | H49: =+SUMPRODUCT(H30:H48,$D30:$D48) | I49: =+SUMPRODUCT(I30:I48,$D30:$D48) | J49: =+SUMPRODUCT(J30:J48,$D30:$D48) | K49: =+SUMPRODUCT(K30:K48,$D30:$D48) | L49: =+SUMPRODUCT(L30:L48,$D30:$D48) | M49: =+SUMPRODUCT(M30:M48,$D30:$D48) | N49: =SUM(N30:N48) | P49: Total (Pre-Vacancy) | R49: =SUM(R30:R48) | S49: =+SUMPRODUCT(S30:S48,$R30:$R48) | T49: =+SUMPRODUCT(T30:T48,$R30:$R48) | U49: =SUM(U30:U48) | W49: Total (Pre-Vacancy) | Y49: =SUM(Y30:Y48) | Z49: =+SUMPRODUCT(Z30:Z48,$Y30:$Y48) | AA49: =+SUMPRODUCT(AA30:AA48,$Y30:$Y48) | AB49: =SUM(AB30:AB48) | AD49: Total (Pre-Vacancy) | AF49: =SUM(AF30:AF48) | AG49: =+SUMPRODUCT(AG30:AG48,$AF30:$AF48) | AH49: =+SUMPRODUCT(AH30:AH48,$AF30:$AF48) | AI49: =SUM(AI30:AI48) | AK49: Total (Pre-Vacancy) | AM49: =SUM(AF30:AF48) | AN49: =+SUMPRODUCT(AG30:AG48,$AF30:$AF48) | AO49: =+SUMPRODUCT(AH30:AH48,$AF30:$AF48) | AP49: =SUM(AP30:AP48)
B51: Year 3 | P51: =+$B51 | W51: =+$B51 | AD51: =+$B51 | AK51: =+$B51
B52: Unit Type | C52: AMI / S8 | D52: # of Units | E52: Avg. SF | F52: Avg. Utilities | G52: Avg. Max LITHC | H52: Net LIHTC | I52: Avg. Max FMR | J52: Net FMR | K52: =+K29 | L52: Gross Rent | M52: Avg. Current Rent | N52: Yrly. Gross Income (Net Rent) | P52: Unit Type | Q52: AMI / S8 | R52: # of Units | S52: Avg. SF | T52: Avg. Utilities | U52: Max Current Vouchers | W52: Unit Type | X52: AMI / S8 | Y52: # of Units | Z52: Avg. SF | AA52: Avg. Utilities | AB52: Max NET LIHTC | AD52: Unit Type | AE52: AMI / S8 | AF52: # of Units | AG52: Avg. SF | AH52: Avg. Utilities | AI52: Max Current Vouchers + NET LIHTC | AK52: Unit Type | AL52: AMI / S8 | AM52: # of Units | AN52: Avg. SF | AO52: Avg. Utilities | AP52: Max Current Vouchers + NET LIHTC
B53: =B30 | C53: =C30 | D53: =$D30 | E53: =E30 | F53: =F30*(1+Dashboard!$P$12) | G53: =G30*(1+Dashboard!$P$11) | H53: =+G53-F53 | I53: =I30*(1+Dashboard!$P$11) | J53: =I53-F53 | K53: =K30*(1+Dashboard!$P$11) | L53: =M53+F53 | M53: =M30*(1+Dashboard!$P$11) | N53: =((M53*D53)*12) | P53: =B53 | Q53: =C53 | R53: =D53 | S53: =E53 | T53: =F53 | U53: =((M53*R53)*12) | W53: =B53 | X53: =C53 | Y53: =D53 | Z53: =E53 | AA53: =F53 | AB53: =((H53*Y53)*12) | AD53: =B53 | AE53: =C53 | AF53: =D53 | AG53: =E53 | AH53: =F53 | AI53: =+MAX(U53,AB53) | AK53: =B53 | AL53: =C53 | AM53: =D53 | AN53: =E53 | AO53: =F53 | AP53: =IF(G53>0,MAX(U53,AB53),N53)
B54: =B31 | C54: =C31 | D54: =$D31 | E54: =E31 | F54: =F31*(1+Dashboard!$P$12) | G54: =G31*(1+Dashboard!$P$11) | H54: =+G54-F54 | I54: =I31*(1+Dashboard!$P$11) | J54: =I54-F54 | K54: =K31*(1+Dashboard!$P$11) | L54: =M54+F54 | M54: =M31*(1+Dashboard!$P$11) | N54: =((M54*D54)*12) | P54: =B54 | Q54: =C54 | R54: =D54 | S54: =E54 | T54: =F54 | U54: =((M54*R54)*12) | W54: =B54 | X54: =C54 | Y54: =D54 | Z54: =E54 | AA54: =F54 | AB54: =((H54*Y54)*12) | AD54: =B54 | AE54: =C54 | AF54: =D54 | AG54: =E54 | AH54: =F54 | AI54: =+MAX(U54,AB54) | AK54: =B54 | AL54: =C54 | AM54: =D54 | AN54: =E54 | AO54: =F54 | AP54: =IF(G54>0,MAX(U54,AB54),N54)
B55: =B32 | C55: =C32 | D55: =$D32 | E55: =E32 | F55: =F32*(1+Dashboard!$P$12) | G55: =G32*(1+Dashboard!$P$11) | H55: =+G55-F55 | I55: =I32*(1+Dashboard!$P$11) | J55: =I55-F55 | K55: =K32*(1+Dashboard!$P$11) | L55: =M55+F55 | M55: =M32*(1+Dashboard!$P$11) | N55: =((M55*D55)*12) | P55: =B55 | Q55: =C55 | R55: =D55 | S55: =E55 | T55: =F55 | U55: =((M55*R55)*12) | W55: =B55 | X55: =C55 | Y55: =D55 | Z55: =E55 | AA55: =F55 | AB55: =((H55*Y55)*12) | AD55: =B55 | AE55: =C55 | AF55: =D55 | AG55: =E55 | AH55: =F55 | AI55: =+MAX(U55,AB55) | AK55: =B55 | AL55: =C55 | AM55: =D55 | AN55: =E55 | AO55: =F55 | AP55: =IF(G55>0,MAX(U55,AB55),N55)
B56: =B33 | C56: =C33 | D56: =$D33 | E56: =E33 | F56: =F33*(1+Dashboard!$P$12) | G56: =G33*(1+Dashboard!$P$11) | H56: =+G56-F56 | I56: =I33*(1+Dashboard!$P$11) | J56: =I56-F56 | K56: =K33*(1+Dashboard!$P$11) | L56: =M56+F56 | M56: =M33*(1+Dashboard!$P$11) | N56: =((M56*D56)*12) | P56: =B56 | Q56: =C56 | R56: =D56 | S56: =E56 | T56: =F56 | U56: =((M56*R56)*12) | W56: =B56 | X56: =C56 | Y56: =D56 | Z56: =E56 | AA56: =F56 | AB56: =((H56*Y56)*12) | AD56: =B56 | AE56: =C56 | AF56: =D56 | AG56: =E56 | AH56: =F56 | AI56: =+MAX(U56,AB56) | AK56: =B56 | AL56: =C56 | AM56: =D56 | AN56: =E56 | AO56: =F56 | AP56: =IF(G56>0,MAX(U56,AB56),N56)
B57: =B34 | C57: =C34 | D57: =$D34 | E57: =E34 | F57: =F34*(1+Dashboard!$P$12) | G57: =G34*(1+Dashboard!$P$11) | H57: =+G57-F57 | I57: =I34*(1+Dashboard!$P$11) | J57: =I57-F57 | K57: =K34*(1+Dashboard!$P$11) | L57: =M57+F57 | M57: =M34*(1+Dashboard!$P$11) | N57: =((M57*D57)*12) | P57: =B57 | Q57: =C57 | R57: =D57 | S57: =E57 | T57: =F57 | U57: =((M57*R57)*12) | W57: =B57 | X57: =C57 | Y57: =D57 | Z57: =E57 | AA57: =F57 | AB57: =((H57*Y57)*12) | AD57: =B57 | AE57: =C57 | AF57: =D57 | AG57: =E57 | AH57: =F57 | AI57: =+MAX(U57,AB57) | AK57: =B57 | AL57: =C57 | AM57: =D57 | AN57: =E57 | AO57: =F57 | AP57: =IF(G57>0,MAX(U57,AB57),N57)
...

Sheet Rent Roll
B3: Unit Statistics | F3: Unit Types | J3: AMI / S8 Breakdown | N3: Total SF | O3: Avg Gross Rent | P3: Avg Net Rent
B4: Occupied | C4: =C6-C5 | D4: =+C4/C6 | F4: =+C13 | G4: =SUMIF(C$13:E$32,F4,E$13:E$32) | H4: =G4/G$10 | J4: =+D17 | K4: =SUMIF(D$13:E$32,J4,E$13:E$32) | L4: =K4/K$10 | N4: =+SUMPRODUCT(E13:E31,F13:F31) | O4: =L33/C$6 | P4: =J33/C6
B5: Vacant | C5: =+ROUND(D5*$C$6,0) | D5: =+Dashboard!P10 | F5: =+C17 | G5: =SUMIF(C$13:E$32,F5,E$13:E$32) | H5: =G5/G$10 | J5: =+D13 | K5: =SUMIF(D$13:E$32,J5,E$13:E$32) | L5: =K5/K$10
B6: Total Units | C6: =+SUM(E13:E31) | D6: =SUM(D4:D5) | F6: =+C20 | G6: =SUMIF(C$13:E$32,F6,E$13:E$32) | H6: =G6/G$10 | J6: =+D14 | K6: =SUMIF(D$13:E$32,J6,E$13:E$32) | L6: =K6/K$10
F7: =+C23 | G7: =SUMIF(C$13:E$32,F7,E$13:E$32) | H7: =G7/G$10 | J7: =+D22 | K7: =SUMIF(D$13:E$32,J7,E$13:E$32) | L7: =K7/K$10
F8: =+C27 | G8: =SUMIF(C$13:E$32,F8,E$13:E$32) | H8: =G8/G$10 | J8: =+D27 | K8: =SUMIF(D$13:E$32,J8,E$13:E$32) | L8: =K8/K$10
F9: =+C28 | G9: =SUMIF(C$13:E$32,F9,E$13:E$32) | H9: =G9/G$10
F10: Total | G10: =SUM(G4:G9) | H10: =SUM(H4:H9) | J10: Total | K10: =SUM(K4:K9) | L10: =SUM(L4:L8)
B12: Unit Set # | C12: Unit Types | D12: AMI / S8 | E12: # of Units | F12: Avg. SF | G12: Avg. Market Rent | H12: Avg. Resident Rent | I12: Avg. Subsidy | J12: Avg. Current Rent | K12: Avg. Utilities | L12: Gross Rent | M12: Avg. Max LIHTC | N12: Net LIHTC | O12: Avg. Max FMR | P12: Net FMR
B13: 1 | C13: 1x1 | D13: 50% AMI | E13: 2 | F13: 701 | H13: 527 | J13: =+(I13+H13) | K13: 65 | L13: =J13+K13 | M13: 651 | N13: =M13-$K13 | O13: 683 | P13: =O13-$K13
B14: =+B13+1 | C14: 1x1 | D14: 60% AMI | E14: 0 | F14: 701 | H14: 0 | J14: =+(I14+H14) | K14: 65 | L14: =J14+K14 | M14: 781 | N14: =M14-$K14 | O14: 683 | P14: =O14-$K14
B15: =+B14+1 | C15: 1x1 | D15: Market | E15: 1 | F15: 701 | H15: 593 | J15: =+(I15+H15) | K15: 0 | L15: =J15+K15 | M15: 0 | N15: =M15-$K15 | O15: 683 | P15: =O15-$K15
B16: =+B15+1 | C16: 1x1 | D16: S8 Voucher | E16: 3 | F16: 701 | H16: 523 | J16: =+(I16+H16) | K16: 65 | L16: =J16+K16 | M16: 781 | N16: =M16-$K16 | O16: 683 | P16: =O16-$K16
B17: =+B16+1 | C17: 2x1.5 | D17: 40% AMI | E17: 1 | F17: 940 | H17: 465 | J17: =+(I17+H17) | K17: 86 | L17: =J17+K17 | M17: 539 | N17: =M17-$K17 | O17: 778 | P17: =O17-$K17
B18: =+B17+1 | C18: 2x1.5 | D18: =+D13 | E18: 3 | F18: 990 | H18: 580 | J18: =+(I18+H18) | K18: 86 | L18: =J18+K18 | M18: 695 | N18: =M18-$K18 | O18: 778 | P18: =O18-$K18
B19: =+B18+1 | C19: 2x1.5 | D19: =+D14 | E19: 2 | F19: 980 | H19: 642 | J19: =+(I19+H19) | K19: 86 | L19: =J19+K19 | M19: 851 | N19: =M19-$K19 | O19: 778 | P19: =O19-$K19
B20: =+B19+1 | C20: 2x2 | D20: =+D18 | E20: 1 | F20: 968 | H20: 610 | J20: =+(I20+H20) | K20: 86 | L20: =J20+K20 | M20: 695 | N20: =M20-$K20 | O20: 778 | P20: =O20-$K20
B21: =+B20+1 | C21: 2x2 | D21: =+D19 | E21: 2 | F21: 968 | H21: 635 | J21: =+(I21+H21) | K21: 86 | L21: =J21+K21 | M21: 851 | N21: =M21-$K21 | O21: 778 | P21: =O21-$K21
B22: =+B21+1 | C22: 2x2 | D22: =+D15 | E22: 0 | F22: 968 | H22: 0 | J22: =+(I22+H22) | K22: 0 | L22: =J22+K22 | M22: 0 | N22: =M22-$K22 | O22: 778 | P22: =O22-$K22
B23: =+B22+1 | C23: 2x2 (TH) | D23: =+D17 | E23: 1 | F23: 1058 | H23: 450 | J23: =+(I23+H23) | K23: 86 | L23: =J23+K23 | M23: 539 | N23: =M23-$K23 | O23: 778 | P23: =O23-$K23
B24: =+B23+1 | C24: 2x2 (TH) | D24: =+D18 | E24: 1 | F24: 1058 | H24: 60 | J24: =+(I24+H24) | K24: 86 | L24: =J24+K24 | M24: 695 | N24: =M24-$K24 | O24: 778 | P24: =O24-$K24
